Traceback (most recent call last):
  File "/Users/joreilly/opt/anaconda3/lib/python3.9/site-packages/jupyter_cache/executors/utils.py", line 51, in single_nb_execution
    executenb(
  File "/Users/joreilly/opt/anaconda3/lib/python3.9/site-packages/nbclient/client.py", line 1204, in execute
    return NotebookClient(nb=nb, resources=resources, km=km, **kwargs).execute()
  File "/Users/joreilly/opt/anaconda3/lib/python3.9/site-packages/nbclient/util.py", line 84, in wrapped
    return just_run(coro(*args, **kwargs))
  File "/Users/joreilly/opt/anaconda3/lib/python3.9/site-packages/nbclient/util.py", line 62, in just_run
    return loop.run_until_complete(coro)
  File "/Users/joreilly/opt/anaconda3/lib/python3.9/asyncio/base_events.py", line 647, in run_until_complete
    return future.result()
  File "/Users/joreilly/opt/anaconda3/lib/python3.9/site-packages/nbclient/client.py", line 663, in async_execute
    await self.async_execute_cell(
  File "/Users/joreilly/opt/anaconda3/lib/python3.9/site-packages/nbclient/client.py", line 965, in async_execute_cell
    await self._check_raise_for_error(cell, cell_index, exec_reply)
  File "/Users/joreilly/opt/anaconda3/lib/python3.9/site-packages/nbclient/client.py", line 862, in _check_raise_for_error
    raise CellExecutionError.from_cell_and_msg(cell, exec_reply_content)
nbclient.exceptions.CellExecutionError: An error occurred while executing the following cell:
------------------
# my best effort in Python - horribly clunky!

nReps=10000
c=np.empty(nReps)
n=len(wb[wb['College']=='Lonsdale'])
print('n = ' + str(n))

# how we got correlation before (already clunky!)
print('r = ' + str(wb[wb['College']=='Lonsdale']['Score_preVac'].corr(wb[wb['College']=='Lonsdale']['Score_postVac'])))
    # convert to a numpy array)
    # convert to a numpy array

for i in range(nReps):
    sample= np.random.Generator.choice(wb[wb['College']=='Lonsdale'][['Score_preVac','Score_postVac']],n,replace=True)
    tmp=np.corrcoef(sample[:,0],sample[:,1])
    c[i]=tmp[0,1]

sns.histplot(c)
plt.show()
------------------

[0;31m---------------------------------------------------------------------------[0m
[0;31mTypeError[0m                                 Traceback (most recent call last)
[0;32m/var/folders/q4/twg1yll54y142rc02m5wwbt40000gr/T/ipykernel_70278/419081113.py[0m in [0;36m<module>[0;34m[0m
[1;32m     12[0m [0;34m[0m[0m
[1;32m     13[0m [0;32mfor[0m [0mi[0m [0;32min[0m [0mrange[0m[0;34m([0m[0mnReps[0m[0;34m)[0m[0;34m:[0m[0;34m[0m[0;34m[0m[0m
[0;32m---> 14[0;31m     [0msample[0m[0;34m=[0m [0mnp[0m[0;34m.[0m[0mrandom[0m[0;34m.[0m[0mGenerator[0m[0;34m.[0m[0mchoice[0m[0;34m([0m[0mwb[0m[0;34m[[0m[0mwb[0m[0;34m[[0m[0;34m'College'[0m[0;34m][0m[0;34m==[0m[0;34m'Lonsdale'[0m[0;34m][0m[0;34m[[0m[0;34m[[0m[0;34m'Score_preVac'[0m[0;34m,[0m[0;34m'Score_postVac'[0m[0;34m][0m[0;34m][0m[0;34m,[0m[0mn[0m[0;34m,[0m[0mreplace[0m[0;34m=[0m[0;32mTrue[0m[0;34m)[0m[0;34m[0m[0;34m[0m[0m
[0m[1;32m     15[0m     [0mtmp[0m[0;34m=[0m[0mnp[0m[0;34m.[0m[0mcorrcoef[0m[0;34m([0m[0msample[0m[0;34m[[0m[0;34m:[0m[0;34m,[0m[0;36m0[0m[0;34m][0m[0;34m,[0m[0msample[0m[0;34m[[0m[0;34m:[0m[0;34m,[0m[0;36m1[0m[0;34m][0m[0;34m)[0m[0;34m[0m[0;34m[0m[0m
[1;32m     16[0m     [0mc[0m[0;34m[[0m[0mi[0m[0;34m][0m[0;34m=[0m[0mtmp[0m[0;34m[[0m[0;36m0[0m[0;34m,[0m[0;36m1[0m[0;34m][0m[0;34m[0m[0;34m[0m[0m

[0;31mTypeError[0m: descriptor 'choice' for 'numpy.random._generator.Generator' objects doesn't apply to a 'DataFrame' object
TypeError: descriptor 'choice' for 'numpy.random._generator.Generator' objects doesn't apply to a 'DataFrame' object

