Traceback (most recent call last):
  File "/Users/joreilly/opt/anaconda3/lib/python3.9/site-packages/jupyter_cache/executors/utils.py", line 51, in single_nb_execution
    executenb(
  File "/Users/joreilly/opt/anaconda3/lib/python3.9/site-packages/nbclient/client.py", line 1269, in execute
    return NotebookClient(nb=nb, resources=resources, km=km, **kwargs).execute()
  File "/Users/joreilly/opt/anaconda3/lib/python3.9/site-packages/nbclient/util.py", line 85, in wrapped
    return just_run(coro(*args, **kwargs))
  File "/Users/joreilly/opt/anaconda3/lib/python3.9/site-packages/nbclient/util.py", line 60, in just_run
    return loop.run_until_complete(coro)
  File "/Users/joreilly/opt/anaconda3/lib/python3.9/asyncio/base_events.py", line 647, in run_until_complete
    return future.result()
  File "/Users/joreilly/opt/anaconda3/lib/python3.9/site-packages/nbclient/client.py", line 707, in async_execute
    await self.async_execute_cell(
  File "/Users/joreilly/opt/anaconda3/lib/python3.9/site-packages/nbclient/client.py", line 1025, in async_execute_cell
    await self._check_raise_for_error(cell, cell_index, exec_reply)
  File "/Users/joreilly/opt/anaconda3/lib/python3.9/site-packages/nbclient/client.py", line 919, in _check_raise_for_error
    raise CellExecutionError.from_cell_and_msg(cell, exec_reply_content)
nbclient.exceptions.CellExecutionError: An error occurred while executing the following cell:
------------------
weather = pandas.read_csv("https://raw.githubusercontent.com/jillxoreilly/StatsCourseBook/main/data/OxfordWeather.csv")
display(weather)
------------------

[0;31m---------------------------------------------------------------------------[0m
[0;31mNameError[0m                                 Traceback (most recent call last)
[0;32m/var/folders/q4/twg1yll54y142rc02m5wwbt40000gr/T/ipykernel_19506/3980356552.py[0m in [0;36m<module>[0;34m[0m
[0;32m----> 1[0;31m [0mweather[0m [0;34m=[0m [0mpandas[0m[0;34m.[0m[0mread_csv[0m[0;34m([0m[0;34m"https://raw.githubusercontent.com/jillxoreilly/StatsCourseBook/main/data/OxfordWeather.csv"[0m[0;34m)[0m[0;34m[0m[0;34m[0m[0m
[0m[1;32m      2[0m [0mdisplay[0m[0;34m([0m[0mweather[0m[0;34m)[0m[0;34m[0m[0;34m[0m[0m

[0;31mNameError[0m: name 'pandas' is not defined
NameError: name 'pandas' is not defined

