Traceback (most recent call last):
  File "/Users/joreilly/opt/anaconda3/lib/python3.9/site-packages/jupyter_cache/executors/utils.py", line 51, in single_nb_execution
    executenb(
  File "/Users/joreilly/opt/anaconda3/lib/python3.9/site-packages/nbclient/client.py", line 1269, in execute
    return NotebookClient(nb=nb, resources=resources, km=km, **kwargs).execute()
  File "/Users/joreilly/opt/anaconda3/lib/python3.9/site-packages/nbclient/util.py", line 85, in wrapped
    return just_run(coro(*args, **kwargs))
  File "/Users/joreilly/opt/anaconda3/lib/python3.9/site-packages/nbclient/util.py", line 60, in just_run
    return loop.run_until_complete(coro)
  File "/Users/joreilly/opt/anaconda3/lib/python3.9/asyncio/base_events.py", line 647, in run_until_complete
    return future.result()
  File "/Users/joreilly/opt/anaconda3/lib/python3.9/site-packages/nbclient/client.py", line 707, in async_execute
    await self.async_execute_cell(
  File "/Users/joreilly/opt/anaconda3/lib/python3.9/site-packages/nbclient/client.py", line 1025, in async_execute_cell
    await self._check_raise_for_error(cell, cell_index, exec_reply)
  File "/Users/joreilly/opt/anaconda3/lib/python3.9/site-packages/nbclient/client.py", line 919, in _check_raise_for_error
    raise CellExecutionError.from_cell_and_msg(cell, exec_reply_content)
nbclient.exceptions.CellExecutionError: An error occurred while executing the following cell:
------------------
nReps=1000
sampleSize=50
p = np.empty(nReps)

for i in range(nReps):
    sample = pop_rNonZero.sample(n=sampleSize)
    p[i] = stats.pearsonr(sample['Maths'], sample['French'], alternative='greater')
    
# How many of our 10000 samples had p<0.05?
np.mean(p<0.05)
------------------

[0;31m---------------------------------------------------------------------------[0m
[0;31mTypeError[0m                                 Traceback (most recent call last)
[0;31mTypeError[0m: float() argument must be a string or a number, not 'PearsonRResult'

The above exception was the direct cause of the following exception:

[0;31mValueError[0m                                Traceback (most recent call last)
[0;32m/var/folders/q4/twg1yll54y142rc02m5wwbt40000gr/T/ipykernel_5138/3587976242.py[0m in [0;36m<module>[0;34m[0m
[1;32m      5[0m [0;32mfor[0m [0mi[0m [0;32min[0m [0mrange[0m[0;34m([0m[0mnReps[0m[0;34m)[0m[0;34m:[0m[0;34m[0m[0;34m[0m[0m
[1;32m      6[0m     [0msample[0m [0;34m=[0m [0mpop_rNonZero[0m[0;34m.[0m[0msample[0m[0;34m([0m[0mn[0m[0;34m=[0m[0msampleSize[0m[0;34m)[0m[0;34m[0m[0;34m[0m[0m
[0;32m----> 7[0;31m     [0mp[0m[0;34m[[0m[0mi[0m[0;34m][0m [0;34m=[0m [0mstats[0m[0;34m.[0m[0mpearsonr[0m[0;34m([0m[0msample[0m[0;34m[[0m[0;34m'Maths'[0m[0;34m][0m[0;34m,[0m [0msample[0m[0;34m[[0m[0;34m'French'[0m[0;34m][0m[0;34m,[0m [0malternative[0m[0;34m=[0m[0;34m'greater'[0m[0;34m)[0m[0;34m[0m[0;34m[0m[0m
[0m[1;32m      8[0m [0;34m[0m[0m
[1;32m      9[0m [0;31m# How many of our 10000 samples had p<0.05?[0m[0;34m[0m[0;34m[0m[0m

[0;31mValueError[0m: setting an array element with a sequence.
ValueError: setting an array element with a sequence.

