Traceback (most recent call last):
  File "/Users/joreilly/opt/anaconda3/lib/python3.9/site-packages/jupyter_cache/executors/utils.py", line 51, in single_nb_execution
    executenb(
  File "/Users/joreilly/opt/anaconda3/lib/python3.9/site-packages/nbclient/client.py", line 1204, in execute
    return NotebookClient(nb=nb, resources=resources, km=km, **kwargs).execute()
  File "/Users/joreilly/opt/anaconda3/lib/python3.9/site-packages/nbclient/util.py", line 84, in wrapped
    return just_run(coro(*args, **kwargs))
  File "/Users/joreilly/opt/anaconda3/lib/python3.9/site-packages/nbclient/util.py", line 62, in just_run
    return loop.run_until_complete(coro)
  File "/Users/joreilly/opt/anaconda3/lib/python3.9/asyncio/base_events.py", line 647, in run_until_complete
    return future.result()
  File "/Users/joreilly/opt/anaconda3/lib/python3.9/site-packages/nbclient/client.py", line 663, in async_execute
    await self.async_execute_cell(
  File "/Users/joreilly/opt/anaconda3/lib/python3.9/site-packages/nbclient/client.py", line 965, in async_execute_cell
    await self._check_raise_for_error(cell, cell_index, exec_reply)
  File "/Users/joreilly/opt/anaconda3/lib/python3.9/site-packages/nbclient/client.py", line 862, in _check_raise_for_error
    raise CellExecutionError.from_cell_and_msg(cell, exec_reply_content)
nbclient.exceptions.CellExecutionError: An error occurred while executing the following cell:
------------------
df = pandas.DataFrame(columns = ['age','colsci','evolved','polviews'])
df.loc[0,:]=[50, 'no', np.NaN, 5]
df
# Code for calculating predicted probability
logistic_model.predict(df)

------------------

[0;31m---------------------------------------------------------------------------[0m
[0;31mAttributeError[0m                            Traceback (most recent call last)
[0;32m~/opt/anaconda3/lib/python3.9/site-packages/statsmodels/base/model.py[0m in [0;36mpredict[0;34m(self, exog, transform, *args, **kwargs)[0m
[1;32m   1136[0m             [0;32mtry[0m[0;34m:[0m[0;34m[0m[0;34m[0m[0m
[0;32m-> 1137[0;31m                 [0mexog[0m [0;34m=[0m [0mdmatrix[0m[0;34m([0m[0mdesign_info[0m[0;34m,[0m [0mexog[0m[0;34m,[0m [0mreturn_type[0m[0;34m=[0m[0;34m"dataframe"[0m[0;34m)[0m[0;34m[0m[0;34m[0m[0m
[0m[1;32m   1138[0m             [0;32mexcept[0m [0mException[0m [0;32mas[0m [0mexc[0m[0;34m:[0m[0;34m[0m[0;34m[0m[0m

[0;32m~/opt/anaconda3/lib/python3.9/site-packages/patsy/highlevel.py[0m in [0;36mdmatrix[0;34m(formula_like, data, eval_env, NA_action, return_type)[0m
[1;32m    289[0m     [0meval_env[0m [0;34m=[0m [0mEvalEnvironment[0m[0;34m.[0m[0mcapture[0m[0;34m([0m[0meval_env[0m[0;34m,[0m [0mreference[0m[0;34m=[0m[0;36m1[0m[0;34m)[0m[0;34m[0m[0;34m[0m[0m
[0;32m--> 290[0;31m     (lhs, rhs) = _do_highlevel_design(formula_like, data, eval_env,
[0m[1;32m    291[0m                                       NA_action, return_type)

[0;32m~/opt/anaconda3/lib/python3.9/site-packages/patsy/highlevel.py[0m in [0;36m_do_highlevel_design[0;34m(formula_like, data, eval_env, NA_action, return_type)[0m
[1;32m    166[0m     [0;32mif[0m [0mdesign_infos[0m [0;32mis[0m [0;32mnot[0m [0;32mNone[0m[0;34m:[0m[0;34m[0m[0;34m[0m[0m
[0;32m--> 167[0;31m         return build_design_matrices(design_infos, data,
[0m[1;32m    168[0m                                      [0mNA_action[0m[0;34m=[0m[0mNA_action[0m[0;34m,[0m[0;34m[0m[0;34m[0m[0m

[0;32m~/opt/anaconda3/lib/python3.9/site-packages/patsy/build.py[0m in [0;36mbuild_design_matrices[0;34m(design_infos, data, NA_action, return_type, dtype)[0m
[1;32m    887[0m             [0;32mif[0m [0mfactor_info[0m [0;32mnot[0m [0;32min[0m [0mfactor_info_to_values[0m[0;34m:[0m[0;34m[0m[0;34m[0m[0m
[0;32m--> 888[0;31m                 [0mvalue[0m[0;34m,[0m [0mis_NA[0m [0;34m=[0m [0m_eval_factor[0m[0;34m([0m[0mfactor_info[0m[0;34m,[0m [0mdata[0m[0;34m,[0m [0mNA_action[0m[0;34m)[0m[0;34m[0m[0;34m[0m[0m
[0m[1;32m    889[0m                 [0mfactor_info_to_isNAs[0m[0;34m[[0m[0mfactor_info[0m[0;34m][0m [0;34m=[0m [0mis_NA[0m[0;34m[0m[0;34m[0m[0m

[0;32m~/opt/anaconda3/lib/python3.9/site-packages/patsy/build.py[0m in [0;36m_eval_factor[0;34m(factor_info, data, NA_action)[0m
[1;32m     77[0m                              [0;34m"I got non-numeric data of type '%s'"[0m[0;34m[0m[0;34m[0m[0m
[0;32m---> 78[0;31m                              [0;34m%[0m [0;34m([0m[0mfactor[0m[0;34m.[0m[0mname[0m[0;34m([0m[0;34m)[0m[0;34m,[0m [0mresult[0m[0;34m.[0m[0mdtype[0m[0;34m)[0m[0;34m,[0m[0;34m[0m[0;34m[0m[0m
[0m[1;32m     79[0m                              factor)

[0;32m~/opt/anaconda3/lib/python3.9/site-packages/pandas/core/generic.py[0m in [0;36m__getattr__[0;34m(self, name)[0m
[1;32m   5574[0m             [0;32mreturn[0m [0mself[0m[0;34m[[0m[0mname[0m[0;34m][0m[0;34m[0m[0;34m[0m[0m
[0;32m-> 5575[0;31m         [0;32mreturn[0m [0mobject[0m[0;34m.[0m[0m__getattribute__[0m[0;34m([0m[0mself[0m[0;34m,[0m [0mname[0m[0;34m)[0m[0;34m[0m[0;34m[0m[0m
[0m[1;32m   5576[0m [0;34m[0m[0m

[0;31mAttributeError[0m: 'DataFrame' object has no attribute 'dtype'

During handling of the above exception, another exception occurred:

[0;31mAttributeError[0m                            Traceback (most recent call last)
[0;32m/var/folders/q4/twg1yll54y142rc02m5wwbt40000gr/T/ipykernel_6792/270826893.py[0m in [0;36m<module>[0;34m[0m
[1;32m      3[0m [0mdf[0m[0;34m[0m[0;34m[0m[0m
[1;32m      4[0m [0;31m# Code for calculating predicted probability[0m[0;34m[0m[0;34m[0m[0m
[0;32m----> 5[0;31m [0mlogistic_model[0m[0;34m.[0m[0mpredict[0m[0;34m([0m[0mdf[0m[0;34m)[0m[0;34m[0m[0;34m[0m[0m
[0m
[0;32m~/opt/anaconda3/lib/python3.9/site-packages/statsmodels/base/model.py[0m in [0;36mpredict[0;34m(self, exog, transform, *args, **kwargs)[0m
[1;32m   1142[0m                        [0;34m'\n\nThe original error message returned by patsy is:\n'[0m[0;34m[0m[0;34m[0m[0m
[1;32m   1143[0m                        '{0}'.format(str(str(exc))))
[0;32m-> 1144[0;31m                 [0;32mraise[0m [0mexc[0m[0;34m.[0m[0m__class__[0m[0;34m([0m[0mmsg[0m[0;34m)[0m[0;34m[0m[0;34m[0m[0m
[0m[1;32m   1145[0m             [0;32mif[0m [0morig_exog_len[0m [0;34m>[0m [0mlen[0m[0;34m([0m[0mexog[0m[0;34m)[0m [0;32mand[0m [0;32mnot[0m [0mis_dict[0m[0;34m:[0m[0;34m[0m[0;34m[0m[0m
[1;32m   1146[0m                 [0;32mif[0m [0mexog_index[0m [0;32mis[0m [0;32mNone[0m[0;34m:[0m[0;34m[0m[0;34m[0m[0m

[0;31mAttributeError[0m: predict requires that you use a DataFrame when predicting from a model
that was created using the formula api.

The original error message returned by patsy is:
'DataFrame' object has no attribute 'dtype'
AttributeError: predict requires that you use a DataFrame when predicting from a model
that was created using the formula api.

The original error message returned by patsy is:
'DataFrame' object has no attribute 'dtype'

