Traceback (most recent call last):
  File "/Users/joreilly/opt/anaconda3/lib/python3.9/site-packages/jupyter_cache/executors/utils.py", line 51, in single_nb_execution
    executenb(
  File "/Users/joreilly/opt/anaconda3/lib/python3.9/site-packages/nbclient/client.py", line 1204, in execute
    return NotebookClient(nb=nb, resources=resources, km=km, **kwargs).execute()
  File "/Users/joreilly/opt/anaconda3/lib/python3.9/site-packages/nbclient/util.py", line 84, in wrapped
    return just_run(coro(*args, **kwargs))
  File "/Users/joreilly/opt/anaconda3/lib/python3.9/site-packages/nbclient/util.py", line 62, in just_run
    return loop.run_until_complete(coro)
  File "/Users/joreilly/opt/anaconda3/lib/python3.9/asyncio/base_events.py", line 647, in run_until_complete
    return future.result()
  File "/Users/joreilly/opt/anaconda3/lib/python3.9/site-packages/nbclient/client.py", line 663, in async_execute
    await self.async_execute_cell(
  File "/Users/joreilly/opt/anaconda3/lib/python3.9/site-packages/nbclient/client.py", line 965, in async_execute_cell
    await self._check_raise_for_error(cell, cell_index, exec_reply)
  File "/Users/joreilly/opt/anaconda3/lib/python3.9/site-packages/nbclient/client.py", line 862, in _check_raise_for_error
    raise CellExecutionError.from_cell_and_msg(cell, exec_reply_content)
nbclient.exceptions.CellExecutionError: An error occurred while executing the following cell:
------------------
df = df[[50],[5],[0]]
df
# Code for calculating predicted probability
#logistic_model.predict([[50,5,0]])

------------------

[0;31m---------------------------------------------------------------------------[0m
[0;31mNameError[0m                                 Traceback (most recent call last)
[0;32m/var/folders/q4/twg1yll54y142rc02m5wwbt40000gr/T/ipykernel_71478/163586980.py[0m in [0;36m<module>[0;34m[0m
[0;32m----> 1[0;31m [0mdf[0m [0;34m=[0m [0mdf[0m[0;34m[[0m[0;34m[[0m[0;36m50[0m[0;34m][0m[0;34m,[0m[0;34m[[0m[0;36m5[0m[0;34m][0m[0;34m,[0m[0;34m[[0m[0;36m0[0m[0;34m][0m[0;34m][0m[0;34m[0m[0;34m[0m[0m
[0m[1;32m      2[0m [0mdf[0m[0;34m[0m[0;34m[0m[0m
[1;32m      3[0m [0;31m# Code for calculating predicted probability[0m[0;34m[0m[0;34m[0m[0m
[1;32m      4[0m [0;31m#logistic_model.predict([[50,5,0]])[0m[0;34m[0m[0;34m[0m[0m

[0;31mNameError[0m: name 'df' is not defined
NameError: name 'df' is not defined

